# üîß Corre√ß√£o do Erro de Banco de Dados no Chatbot

## üö® Problema Identificado

O chatbot est√° falhando ao processar mensagens com o erro:
```
sqlite3.OperationalError: unable to open database file
```

## üîç Diagn√≥stico

O sistema est√° caindo no fallback SQLite quando deveria usar o Supabase. Isso indica que:

1. **Vari√°veis de ambiente n√£o est√£o configuradas corretamente no Vercel**
2. **Conex√£o com Supabase pode estar falhando**
3. **Sistema de fallback SQLite tinha problemas de permiss√£o no `/tmp`**

## ‚úÖ Corre√ß√µes Aplicadas

### 1. **Sistema de Banco Melhorado** 
- ‚úÖ Adicionado teste de conectividade antes de usar qualquer banco
- ‚úÖ Fallback robusto: Supabase ‚Üí SQLite em /tmp ‚Üí SQLite em mem√≥ria
- ‚úÖ Logs detalhados para diagn√≥stico
- ‚úÖ Tratamento de permiss√µes no diret√≥rio `/tmp`

### 2. **Debug Script Criado**
- ‚úÖ Script `debug_database.py` para testar conex√µes
- ‚úÖ Verifica√ß√£o de todas as vari√°veis de ambiente
- ‚úÖ Teste de conectividade completo

## üöÄ Passos para Corrigir

### Passo 1: Verificar Vari√°veis no Vercel

1. **Acessar Vercel Dashboard**: https://vercel.com/dashboard
2. **Ir para o projeto do chatbot**
3. **Acessar Settings ‚Üí Environment Variables**
4. **Verificar se est√£o configuradas**:

```bash
# ‚úÖ OBRIGAT√ìRIO - Banco de Dados
DATABASE_URL=postgresql://postgres.feqylqrphdpeeusdyeyw:eyJhbGciOiJIUzI1NiIsInR5cCI6IkpXVCJ9.eyJpc3MiOiJzdXBhYmFzZSIsInJlZiI6ImZlcXlscXJwaGRwZWV1c2R5ZXl3Iiwicm9sZSI6InNlcnZpY2Vfcm9sZSIsImlhdCI6MTc1Mzg3NDA5OSwiZXhwIjoyMDY5NDUwMDk5fQ.gEF_cKRzAtDklZuTueVX_1XzaFrGONzECBS4tt13uIc@feqylqrphdpeeusdyeyw.supabase.co:5432/postgres

# ‚úÖ OBRIGAT√ìRIO - Supabase
SUPABASE_URL=https://feqylqrphdpeeusdyeyw.supabase.co
SUPABASE_SERVICE_ROLE_KEY=eyJhbGciOiJIUzI1NiIsInR5cCI6IkpXVCJ9.eyJpc3MiOiJzdXBhYmFzZSIsInJlZiI6ImZlcXlscXJwaGRwZWV1c2R5ZXl3Iiwicm9sZSI6InNlcnZpY2Vfcm9sZSIsImlhdCI6MTc1Mzg3NDA5OSwiZXhwIjoyMDY5NDUwMDk5fQ.gEF_cKRzAtDklZuTueVX_1XzaFrGONzECBS4tt13uIc

# ‚úÖ OBRIGAT√ìRIO - Z-API  
ZAPI_INSTANCE_ID=3E4F7360B552F0C2DBCB9E6774402775
ZAPI_TOKEN=0BDEFB65E4B5E5615697BCD6
ZAPI_CLIENT_TOKEN=Fe13336af87e3482682a1f5f54a8fc83aS

# ‚úÖ OBRIGAT√ìRIO - Configura√ß√£o
ENVIRONMENT=production
VERCEL=1
```

### Passo 2: Fazer Deploy das Corre√ß√µes

1. **Commit das mudan√ßas**:
```bash
git add .
git commit -m "üîß Corre√ß√£o sistema de banco robusto para Vercel"
git push origin main
```

2. **Triggerar redeploy no Vercel** (autom√°tico ap√≥s push)

### Passo 3: Testar Conectividade

1. **Executar localmente o debug**:
```bash
python debug_database.py
```

2. **Verificar logs no Vercel** ap√≥s deploy

## üîç Verifica√ß√£o P√≥s-Deploy

### 1. Testar Bot no WhatsApp
- Enviar mensagem "oi" para o bot
- Verificar se recebe o menu principal
- Monitorar logs do Vercel

### 2. Monitorar Logs do Vercel
- Verificar se aparecem os logs de debug:
  - `üîç [DEBUG] IS_VERCEL: True`
  - `‚úÖ [DEBUG] DATABASE_URL funcionando!` ou `‚úÖ [DEBUG] Supabase funcionando!`

### 3. Se Ainda Houver Problemas
- Verificar se as credenciais do Supabase est√£o corretas
- Testar manualmente a conex√£o do Supabase
- Verificar se as tabelas foram criadas no Supabase

## üìä Sistema de Fallback Implementado

```
1. DATABASE_URL (direta) 
   ‚Üì (se falhar)
2. Supabase (constru√≠da) 
   ‚Üì (se falhar)
3. SQLite em /tmp 
   ‚Üì (se falhar)
4. SQLite em mem√≥ria (√∫ltimo recurso)
```

## ‚ö†Ô∏è Notas Importantes

- **SQLite em mem√≥ria**: Dados s√£o perdidos a cada restart
- **Supabase √© preferencial**: Dados persistem e s√£o compartilhados
- **Logs detalhados**: Facilitam o diagn√≥stico de problemas
- **Teste autom√°tico**: Sistema verifica conectividade antes de usar

## üìû Teste Final

Ap√≥s aplicar as corre√ß√µes:
1. Envie "oi" para o WhatsApp do bot
2. Deve receber o menu principal
3. Logs do Vercel devem mostrar conex√£o bem-sucedida

Se o problema persistir, verifique se todas as vari√°veis de ambiente est√£o configuradas corretamente no Vercel.